<?xml version="1.0"?>
<robot xmlns:xacro="http://www.ros.org/wiki/xacro" name="delivery_robot">

  <!-- ═══════════════════════════════════════════
       PROPERTIES
  ═══════════════════════════════════════════ -->
  <xacro:property name="base_length"  value="0.45"/>
  <xacro:property name="base_width"   value="0.32"/>
  <xacro:property name="base_height"  value="0.18"/>
  <xacro:property name="base_mass"    value="8.0"/>

  <xacro:property name="wheel_radius" value="0.065"/>
  <xacro:property name="wheel_width"  value="0.04"/>
  <xacro:property name="wheel_mass"   value="0.5"/>
  <xacro:property name="wheel_separation" value="0.30"/>  <!-- distance between left/right wheels -->

  <xacro:property name="caster_radius" value="0.025"/>
  <xacro:property name="lidar_height"  value="0.22"/>

  <!-- ═══════════════════════════════════════════
       MATERIALS
  ═══════════════════════════════════════════ -->
  <material name="robot_grey">
    <color rgba="0.3 0.3 0.35 1.0"/>
  </material>
  <material name="wheel_black">
    <color rgba="0.1 0.1 0.1 1.0"/>
  </material>
  <material name="lidar_blue">
    <color rgba="0.1 0.4 0.8 1.0"/>
  </material>
  <material name="caster_silver">
    <color rgba="0.7 0.7 0.7 1.0"/>
  </material>

  <!-- ═══════════════════════════════════════════
       BASE FOOTPRINT  (ground-level reference)
  ═══════════════════════════════════════════ -->
  <link name="base_footprint"/>

  <joint name="base_footprint_joint" type="fixed">
    <parent link="base_footprint"/>
    <child  link="base_link"/>
    <origin xyz="0 0 ${wheel_radius}" rpy="0 0 0"/>
  </joint>

  <!-- ═══════════════════════════════════════════
       BASE LINK  (robot body)
  ═══════════════════════════════════════════ -->
  <link name="base_link">
    <visual>
      <origin xyz="0 0 ${base_height/2}" rpy="0 0 0"/>
      <geometry>
        <box size="${base_length} ${base_width} ${base_height}"/>
      </geometry>
      <material name="robot_grey"/>
    </visual>
    <collision>
      <origin xyz="0 0 ${base_height/2}" rpy="0 0 0"/>
      <geometry>
        <box size="${base_length} ${base_width} ${base_height}"/>
      </geometry>
    </collision>
    <inertial>
      <origin xyz="0 0 ${base_height/2}" rpy="0 0 0"/>
      <mass value="${base_mass}"/>
      <inertia
        ixx="${base_mass/12*(base_width*base_width + base_height*base_height)}"
        iyy="${base_mass/12*(base_length*base_length + base_height*base_height)}"
        izz="${base_mass/12*(base_length*base_length + base_width*base_width)}"
        ixy="0" ixz="0" iyz="0"/>
    </inertial>
  </link>

  <!-- ═══════════════════════════════════════════
       WHEEL MACRO
  ═══════════════════════════════════════════ -->
  <xacro:macro name="wheel" params="name y_reflect">
    <link name="${name}_wheel">
      <visual>
        <origin xyz="0 0 0" rpy="${pi/2} 0 0"/>
        <geometry>
          <cylinder radius="${wheel_radius}" length="${wheel_width}"/>
        </geometry>
        <material name="wheel_black"/>
      </visual>
      <collision>
        <origin xyz="0 0 0" rpy="${pi/2} 0 0"/>
        <geometry>
          <cylinder radius="${wheel_radius}" length="${wheel_width}"/>
        </geometry>
      </collision>
      <inertial>
        <origin xyz="0 0 0" rpy="${pi/2} 0 0"/>
        <mass value="${wheel_mass}"/>
        <inertia
          ixx="${wheel_mass/12*(3*wheel_radius*wheel_radius + wheel_width*wheel_width)}"
          iyy="${wheel_mass/12*(3*wheel_radius*wheel_radius + wheel_width*wheel_width)}"
          izz="${wheel_mass/2*wheel_radius*wheel_radius}"
          ixy="0" ixz="0" iyz="0"/>
      </inertial>
    </link>

    <joint name="${name}_wheel_joint" type="continuous">
      <parent link="base_link"/>
      <child  link="${name}_wheel"/>
      <origin xyz="-0.05 ${y_reflect * wheel_separation/2} 0" rpy="0 0 0"/>
      <axis xyz="0 1 0"/>
      <dynamics damping="0.1" friction="0.1"/>
    </joint>
  </xacro:macro>

  <xacro:wheel name="left"  y_reflect=" 1"/>
  <xacro:wheel name="right" y_reflect="-1"/>

  <!-- ═══════════════════════════════════════════
       FRONT CASTER WHEEL
  ═══════════════════════════════════════════ -->
  <link name="caster_link">
    <visual>
      <geometry><sphere radius="${caster_radius}"/></geometry>
      <material name="caster_silver"/>
    </visual>
    <collision>
      <geometry><sphere radius="${caster_radius}"/></geometry>
    </collision>
    <inertial>
      <mass value="0.1"/>
      <inertia ixx="0.0001" iyy="0.0001" izz="0.0001" ixy="0" ixz="0" iyz="0"/>
    </inertial>
  </link>

  <joint name="caster_joint" type="fixed">
    <parent link="base_link"/>
    <child  link="caster_link"/>
    <origin xyz="0.18 0 ${-wheel_radius + caster_radius}" rpy="0 0 0"/>
  </joint>

  <!-- ═══════════════════════════════════════════
       IMU LINK
  ═══════════════════════════════════════════ -->
  <link name="imu_link">
    <visual>
      <geometry><box size="0.03 0.03 0.01"/></geometry>
      <material name="lidar_blue"/>
    </visual>
    <inertial>
      <mass value="0.01"/>
      <inertia ixx="0.0001" iyy="0.0001" izz="0.0001" ixy="0" ixz="0" iyz="0"/>
    </inertial>
  </link>

  <joint name="imu_joint" type="fixed">
    <parent link="base_link"/>
    <child  link="imu_link"/>
    <origin xyz="0 0 ${base_height}" rpy="0 0 0"/>
  </joint>

  <!-- ═══════════════════════════════════════════
       LIDAR LINK  (2D RPLiDAR-style)
       frame_id will be "base_scan" to match
       what Gazebo publishes
  ═══════════════════════════════════════════ -->
  <link name="base_scan">
    <visual>
      <origin xyz="0 0 0" rpy="0 0 0"/>
      <geometry>
        <cylinder radius="0.04" length="0.06"/>
      </geometry>
      <material name="lidar_blue"/>
    </visual>
    <collision>
      <geometry>
        <cylinder radius="0.04" length="0.06"/>
      </geometry>
    </collision>
    <inertial>
      <mass value="0.15"/>
      <inertia ixx="0.0001" iyy="0.0001" izz="0.0001" ixy="0" ixz="0" iyz="0"/>
    </inertial>
  </link>

  <joint name="lidar_joint" type="fixed">
    <parent link="base_link"/>
    <child  link="base_scan"/>
    <origin xyz="0.18 0 ${lidar_height}" rpy="0 0 0"/>
  </joint>

  <!-- Keep laser_frame as alias for backward compat -->
  <link name="laser_frame"/>
  <joint name="laser_frame_joint" type="fixed">
    <parent link="base_scan"/>
    <child  link="laser_frame"/>
    <origin xyz="0 0 0" rpy="0 0 0"/>
  </joint>

  <!-- ═══════════════════════════════════════════
       GAZEBO HARMONIC PLUGINS
  ═══════════════════════════════════════════ -->

  <!-- Differential drive controller -->
  <gazebo>
    <plugin filename="gz-sim-diff-drive-system"
            name="gz::sim::systems::DiffDrive">
      <left_joint>left_wheel_joint</left_joint>
      <right_joint>right_wheel_joint</right_joint>
      <wheel_separation>${wheel_separation}</wheel_separation>
      <wheel_radius>${wheel_radius}</wheel_radius>
      <odom_publish_frequency>20</odom_publish_frequency>
      <topic>cmd_vel</topic>
      <odom_topic>odom</odom_topic>
      <frame_id>odom</frame_id>
      <child_frame_id>base_footprint</child_frame_id>
      <tf_topic>/tf</tf_topic>
    </plugin>
  </gazebo>

  <!-- Joint state publisher (for wheel angles) -->
  <gazebo>
    <plugin filename="gz-sim-joint-state-publisher-system"
            name="gz::sim::systems::JointStatePublisher">
      <topic>joint_states</topic>
      <joint_name>left_wheel_joint</joint_name>
      <joint_name>right_wheel_joint</right_joint>
    </plugin>
  </gazebo>

  <!-- 2D LiDAR sensor -->
  <gazebo reference="base_scan">
    <sensor name="lidar" type="gpu_lidar">
      <topic>scan</topic>
      <update_rate>10</update_rate>
      <gz_frame_id>base_scan</gz_frame_id>
      <lidar>
        <scan>
          <horizontal>
            <samples>360</samples>
            <resolution>1</resolution>
            <min_angle>-3.14159</min_angle>
            <max_angle>3.14159</max_angle>
          </horizontal>
        </scan>
        <range>
          <min>0.12</min>
          <max>12.0</max>
          <resolution>0.01</resolution>
        </range>
        <noise>
          <type>gaussian</type>
          <mean>0.0</mean>
          <stddev>0.01</stddev>
        </noise>
      </lidar>
      <always_on>true</always_on>
      <visualize>true</visualize>
    </sensor>
  </gazebo>

  <!-- IMU sensor -->
  <gazebo reference="imu_link">
    <sensor name="imu_sensor" type="imu">
      <topic>imu</topic>
      <update_rate>100</update_rate>
      <gz_frame_id>imu_link</gz_frame_id>
      <always_on>true</always_on>
      <imu>
        <angular_velocity>
          <x><noise type="gaussian"><mean>0</mean><stddev>0.009</stddev></noise></x>
          <y><noise type="gaussian"><mean>0</mean><stddev>0.009</stddev></noise></y>
          <z><noise type="gaussian"><mean>0</mean><stddev>0.009</stddev></noise></z>
        </angular_velocity>
        <linear_acceleration>
          <x><noise type="gaussian"><mean>0</mean><stddev>0.021</stddev></noise></x>
          <y><noise type="gaussian"><mean>0</mean><stddev>0.021</stddev></noise></y>
          <z><noise type="gaussian"><mean>0</mean><stddev>0.021</stddev></noise></z>
        </linear_acceleration>
      </imu>
    </sensor>
  </gazebo>

  <!-- Caster wheel — zero friction so it slides freely -->
  <gazebo reference="caster_link">
    <mu1>0.0</mu1>
    <mu2>0.0</mu2>
  </gazebo>

</robot>
